<?xml version="1.0" ?>
<robot name="gripper_2" xmlns:xacro="http://www.ros.org/wiki/xacro">

<!--<xacro:include filename="$(find gripper_2_description)/urdf/materials.xacro" />
<xacro:include filename="$(find gripper_2_description)/urdf/gripper_2.trans" />
<xacro:include filename="$(find gripper_2_description)/urdf/gripper_2.gazebo" /> -->

<link name="base_link">
  <inertial>
    <origin xyz="0.0010791026524495444 0.029788329952492424 0.001499999797088182" rpy="0 0 0"/>
    <mass value="0.02735527895476827"/>
    <inertia ixx="9e-06" iyy="4e-06" izz="1.4e-05" ixy="-0.0" iyz="0.0" ixz="0.0"/>
  </inertial>
  <visual>
    <origin xyz="0 0 0" rpy="0 0 0"/>
    <geometry>
      <mesh filename="file://$(find gripper_2_description)/meshes/base_link.stl" scale="0.001 0.001 0.001"/>
    </geometry>

  </visual>
  <collision>
    <origin xyz="0 0 0" rpy="0 0 0"/>
    <geometry>
      <mesh filename="file://$(find gripper_2_description)/meshes/base_link.stl" scale="0.001 0.001 0.001"/>
    </geometry>
  </collision>
</link>

<link name="Spur_Gear__24_teeth__1">
  <inertial>
    <origin xyz="-6.206601340312187e-05 0.005226491534591884 0.001500000000000003" rpy="0 0 0"/>
    <mass value="0.01683019922617145"/>
    <inertia ixx="2e-06" iyy="1e-06" izz="3e-06" ixy="0.0" iyz="0.0" ixz="0.0"/>
  </inertial>
  <visual>
    <origin xyz="0.0135 -0.0376 -0.003" rpy="0 0 0"/>
    <geometry>
      <mesh filename="file://$(find gripper_2_description)/meshes/Spur_Gear__24_teeth__1.stl" scale="0.001 0.001 0.001"/>
    </geometry>

  </visual>
  <collision>
    <origin xyz="0.0135 -0.0376 -0.003" rpy="0 0 0"/>
    <geometry>
      <mesh filename="file://$(find gripper_2_description)/meshes/Spur_Gear__24_teeth__1.stl" scale="0.001 0.001 0.001"/>
    </geometry>
  </collision>
</link>

<link name="Spur_Gear__24_teeth___1__1">
  <inertial>
    <origin xyz="6.559441729435053e-05 0.005252566038083016 0.0015000000000000013" rpy="0 0 0"/>
    <mass value="0.016891040258003677"/>
    <inertia ixx="2e-06" iyy="1e-06" izz="3e-06" ixy="-0.0" iyz="-0.0" ixz="0.0"/>
  </inertial>
  <visual>
    <origin xyz="-0.0135 -0.0376 -0.003" rpy="0 0 0"/>
    <geometry>
      <mesh filename="file://$(find gripper_2_description)/meshes/Spur_Gear__24_teeth___1__1.stl" scale="0.001 0.001 0.001"/>
    </geometry>

  </visual>
  <collision>
    <origin xyz="-0.0135 -0.0376 -0.003" rpy="0 0 0"/>
    <geometry>
      <mesh filename="file://$(find gripper_2_description)/meshes/Spur_Gear__24_teeth___1__1.stl" scale="0.001 0.001 0.001"/>
    </geometry>
  </collision>
</link>

<link name="Component2_1">
  <inertial>
    <origin xyz="-0.0001956971590490646 0.015498762335775441 0.0015000000000000005" rpy="0 0 0"/>
    <mass value="0.0031908766234954927"/>
    <inertia ixx="0.0" iyy="0.0" izz="0.0" ixy="0.0" iyz="0.0" ixz="0.0"/>
  </inertial>
  <visual>
    <origin xyz="0.00524 -0.058 -0.003" rpy="0 0 0"/>
    <geometry>
      <mesh filename="file://$(find gripper_2_description)/meshes/Component2_1.stl" scale="0.001 0.001 0.001"/>
    </geometry>

  </visual>
  <collision>
    <origin xyz="0.00524 -0.058 -0.003" rpy="0 0 0"/>
    <geometry>
      <mesh filename="file://$(find gripper_2_description)/meshes/Component2_1.stl" scale="0.001 0.001 0.001"/>
    </geometry>
  </collision>
</link>

<link name="Component1_1">
  <inertial>
    <origin xyz="-0.002713754299147303 0.0030830558113210255 -0.0014999999999999996" rpy="0 0 0"/>
    <mass value="0.011969191017707777"/>
    <inertia ixx="3e-06" iyy="0.0" izz="4e-06" ixy="-0.0" iyz="0.0" ixz="0.0"/>
  </inertial>
  <visual>
    <origin xyz="0.005632 -0.088998 -0.003" rpy="0 0 0"/>
    <geometry>
      <mesh filename="file://$(find gripper_2_description)/meshes/Component1_1.stl" scale="0.001 0.001 0.001"/>
    </geometry>

  </visual>
  <collision>
    <origin xyz="0.005632 -0.088998 -0.003" rpy="0 0 0"/>
    <geometry>
      <mesh filename="file://$(find gripper_2_description)/meshes/Component1_1.stl" scale="0.001 0.001 0.001"/>
    </geometry>
  </collision>
</link>

<link name="Component1_2">
  <inertial>
    <origin xyz="0.005522245700852697 0.023483055811321013 -0.0014999999999999996" rpy="0 0 0"/>
    <mass value="0.011969191017707777"/>
    <inertia ixx="3e-06" iyy="0.0" izz="4e-06" ixy="-0.0" iyz="0.0" ixz="0.0"/>
  </inertial>
  <visual>
    <origin xyz="0.013868 -0.068598 -0.003" rpy="0 0 0"/>
    <geometry>
      <mesh filename="file://$(find gripper_2_description)/meshes/Component1_1.stl" scale="0.001 0.001 0.001"/>
    </geometry>

  </visual>
  <collision>
    <origin xyz="0.013868 -0.068598 -0.003" rpy="0 0 0"/>
    <geometry>
      <mesh filename="file://$(find gripper_2_description)/meshes/Component1_1.stl" scale="0.001 0.001 0.001"/>
    </geometry>
  </collision>
</link>

<link name="Component1_Mirror__1">
  <inertial>
    <origin xyz="0.0027136991133458414 0.0030838151567817718 -0.0015000000000000007" rpy="0 0 0"/>
    <mass value="0.011969191017707777"/>
    <inertia ixx="3e-06" iyy="0.0" izz="4e-06" ixy="0.0" iyz="0.0" ixz="-0.0"/>
  </inertial>
  <visual>
    <origin xyz="-0.005651 -0.088997 -0.003" rpy="0 0 0"/>
    <geometry>
      <mesh filename="file://$(find gripper_2_description)/meshes/Component1_Mirror__1.stl" scale="0.001 0.001 0.001"/>
    </geometry>

  </visual>
  <collision>
    <origin xyz="-0.005651 -0.088997 -0.003" rpy="0 0 0"/>
    <geometry>
      <mesh filename="file://$(find gripper_2_description)/meshes/Component1_Mirror__1.stl" scale="0.001 0.001 0.001"/>
    </geometry>
  </collision>
</link>

<link name="Component2_Mirror__1">
  <inertial>
    <origin xyz="0.00020517219558644287 0.015498639694026782 0.0015000000000000005" rpy="0 0 0"/>
    <mass value="0.0031908766234954927"/>
    <inertia ixx="0.0" iyy="0.0" izz="0.0" ixy="-0.0" iyz="-0.0" ixz="-0.0"/>
  </inertial>
  <visual>
    <origin xyz="-0.00524 -0.058 -0.003" rpy="0 0 0"/>
    <geometry>
      <mesh filename="file://$(find gripper_2_description)/meshes/Component2_Mirror__1.stl" scale="0.001 0.001 0.001"/>
    </geometry>

  </visual>
  <collision>
    <origin xyz="-0.00524 -0.058 -0.003" rpy="0 0 0"/>
    <geometry>
      <mesh filename="file://$(find gripper_2_description)/meshes/Component2_Mirror__1.stl" scale="0.001 0.001 0.001"/>
    </geometry>
  </collision>
</link>

<link name="Component1_Mirror__2">
  <inertial>
    <origin xyz="-0.005522300886654159 0.023483815156781773 -0.0015000000000000007" rpy="0 0 0"/>
    <mass value="0.011969191017707777"/>
    <inertia ixx="3e-06" iyy="0.0" izz="4e-06" ixy="0.0" iyz="0.0" ixz="-0.0"/>
  </inertial>
  <visual>
    <origin xyz="-0.013887 -0.068597 -0.003" rpy="0 0 0"/>
    <geometry>
      <mesh filename="file://$(find gripper_2_description)/meshes/Component1_Mirror__1.stl" scale="0.001 0.001 0.001"/>
    </geometry>

  </visual>
  <collision>
    <origin xyz="-0.013887 -0.068597 -0.003" rpy="0 0 0"/>
    <geometry>
      <mesh filename="file://$(find gripper_2_description)/meshes/Component1_Mirror__1.stl" scale="0.001 0.001 0.001"/>
    </geometry>
  </collision>
</link>

<joint name="Revolute 1" type="continuous">
  <origin xyz="-0.0135 0.0376 0.003" rpy="0 0 0"/>
  <parent link="base_link"/>
  <child link="Spur_Gear__24_teeth__1"/>
  <axis xyz="0.0 0.0 -1.0"/>
</joint>

<joint name="Revolute 2" type="revolute">
  <origin xyz="0.0135 0.0376 0.003" rpy="0 0 0"/>
  <parent link="base_link"/>
  <child link="Spur_Gear__24_teeth___1__1"/>
  <axis xyz="0.0 0.0 -1.0"/>
  <limit upper="2.86234" lower="0.907571" effort="100" velocity="100"/>
</joint>

<joint name="Revolute 3" type="continuous">
  <origin xyz="-0.00524 0.058 0.003" rpy="0 0 0"/>
  <parent link="base_link"/>
  <child link="Component2_1"/>
  <axis xyz="0.0 0.0 -1.0"/>
</joint>

<joint name="Revolute 4" type="continuous">
  <origin xyz="-0.008628 0.010598 0.0" rpy="0 0 0"/>
  <parent link="Component2_1"/>
  <child link="Component1_1"/>
  <axis xyz="-0.0 0.0 -1.0"/>
</joint>

<joint name="Revolute 5" type="continuous">
  <origin xyz="-0.000368 0.030998 0.0" rpy="0 0 0"/>
  <parent link="Spur_Gear__24_teeth__1"/>
  <child link="Component1_1"/>
  <axis xyz="0.0 -0.0 1.0"/>
</joint>

<joint name="Revolute 6" type="continuous">
  <origin xyz="0.008647 0.010597 0.0" rpy="0 0 0"/>
  <parent link="Component2_Mirror__1"/>
  <child link="Component1_Mirror__1"/>
  <axis xyz="0.0 0.0 1.0"/>
</joint>

<joint name="Revolute 7" type="continuous">
  <origin xyz="0.00524 0.058 0.003" rpy="0 0 0"/>
  <parent link="base_link"/>
  <child link="Component2_Mirror__1"/>
  <axis xyz="0.0 0.0 -1.0"/>
</joint>

<joint name="Revolute 8" type="continuous">
  <origin xyz="0.000387 0.030997 0.0" rpy="0 0 0"/>
  <parent link="Spur_Gear__24_teeth___1__1"/>
  <child link="Component1_Mirror__1"/>
  <axis xyz="0.0 0.0 1.0"/>
</joint>

</robot>
