<?xml version="1.0" ?>
<robot name="Gwenbot" xmlns:xacro="http://www.ros.org/wiki/xacro">

<xacro:include filename="$(find Gwenbot_description)/urdf/materials.xacro" />
<xacro:include filename="$(find Gwenbot_description)/urdf/Gwenbot.trans" />
<xacro:include filename="$(find Gwenbot_description)/urdf/Gwenbot.gazebo" />
<link name="base_link">
  <inertial>
    <origin xyz="0.0 4.0933704664107524e-17 0.28274077295443034" rpy="0 0 0"/>
    <mass value="446.50748513498274"/>
    <inertia ixx="10.833281" iyy="10.833281" izz="17.479869" ixy="0.0" iyz="0.0" ixz="0.0"/>
  </inertial>
  <visual>
    <origin xyz="0 0 0" rpy="0 0 0"/>
    <geometry>
      <mesh filename="file://$(find Gwenbot_description)/meshes/base_link.stl" scale="0.001 0.001 0.001"/>
    </geometry>
    <material name="silver"/>
  </visual>
  <collision>
    <origin xyz="0 0 0" rpy="0 0 0"/>
    <geometry>
      <mesh filename="file://$(find Gwenbot_description)/meshes/base_link.stl" scale="0.001 0.001 0.001"/>
    </geometry>
  </collision>
</link>

<link name="leg_1_link_2_1">
  <inertial>
    <origin xyz="0.037371706663995446 0.09743794775494169 0.09744152705144904" rpy="0 0 0"/>
    <mass value="26.110950879591996"/>
    <inertia ixx="0.363269" iyy="0.193803" izz="0.193792" ixy="1.1e-05" iyz="-0.154975" ixz="1.1e-05"/>
  </inertial>
  <visual>
    <origin xyz="-0.195 -0.34 -0.24" rpy="0 0 0"/>
    <geometry>
      <mesh filename="file://$(find Gwenbot_description)/meshes/leg_1_link_2_1.stl" scale="0.001 0.001 0.001"/>
    </geometry>
    <material name="silver"/>
  </visual>
  <collision>
    <origin xyz="-0.195 -0.34 -0.24" rpy="0 0 0"/>
    <geometry>
      <mesh filename="file://$(find Gwenbot_description)/meshes/leg_1_link_2_1.stl" scale="0.001 0.001 0.001"/>
    </geometry>
  </collision>
</link>

<link name="leg_1_link_3_1">
  <inertial>
    <origin xyz="-0.03487554397484535 0.161390400385248 -0.08069565156547553" rpy="0 0 0"/>
    <mass value="29.57680033690642"/>
    <inertia ixx="0.597322" iyy="0.149521" izz="0.471799" ixy="-2e-05" iyz="0.214852" ixz="1e-05"/>
  </inertial>
  <visual>
    <origin xyz="-0.195 -0.554944 -0.454952" rpy="0 0 0"/>
    <geometry>
      <mesh filename="file://$(find Gwenbot_description)/meshes/leg_1_link_3_1.stl" scale="0.001 0.001 0.001"/>
    </geometry>
    <material name="silver"/>
  </visual>
  <collision>
    <origin xyz="-0.195 -0.554944 -0.454952" rpy="0 0 0"/>
    <geometry>
      <mesh filename="file://$(find Gwenbot_description)/meshes/leg_1_link_3_1.stl" scale="0.001 0.001 0.001"/>
    </geometry>
  </collision>
</link>

<link name="leg_1_link_4_1">
  <inertial>
    <origin xyz="0.03697762399539972 -0.01388151242503266 -0.10205645983051953" rpy="0 0 0"/>
    <mass value="19.12295749707098"/>
    <inertia ixx="0.184653" iyy="0.17484" izz="0.027319" ixy="3e-06" iyz="-0.020683" ixz="4.1e-05"/>
  </inertial>
  <visual>
    <origin xyz="-0.195 -0.904944 -0.279952" rpy="0 0 0"/>
    <geometry>
      <mesh filename="file://$(find Gwenbot_description)/meshes/leg_1_link_4_1.stl" scale="0.001 0.001 0.001"/>
    </geometry>
    <material name="silver"/>
  </visual>
  <collision>
    <origin xyz="-0.195 -0.904944 -0.279952" rpy="0 0 0"/>
    <geometry>
      <mesh filename="file://$(find Gwenbot_description)/meshes/leg_1_link_4_1.stl" scale="0.001 0.001 0.001"/>
    </geometry>
  </collision>
</link>

<link name="leg_2_link_2_1">
  <inertial>
    <origin xyz="-0.03737170666399556 0.0974379477549418 0.09744152705144915" rpy="0 0 0"/>
    <mass value="26.110950879591993"/>
    <inertia ixx="0.363269" iyy="0.193803" izz="0.193792" ixy="-1.1e-05" iyz="-0.154975" ixz="-1.1e-05"/>
  </inertial>
  <visual>
    <origin xyz="0.195 -0.34 -0.24" rpy="0 0 0"/>
    <geometry>
      <mesh filename="file://$(find Gwenbot_description)/meshes/leg_2_link_2_1.stl" scale="0.001 0.001 0.001"/>
    </geometry>
    <material name="silver"/>
  </visual>
  <collision>
    <origin xyz="0.195 -0.34 -0.24" rpy="0 0 0"/>
    <geometry>
      <mesh filename="file://$(find Gwenbot_description)/meshes/leg_2_link_2_1.stl" scale="0.001 0.001 0.001"/>
    </geometry>
  </collision>
</link>

<link name="leg_2_link_3_1">
  <inertial>
    <origin xyz="0.03487554397484535 0.1613904003852481 -0.08069565156547548" rpy="0 0 0"/>
    <mass value="29.576800336906405"/>
    <inertia ixx="0.597322" iyy="0.149521" izz="0.471799" ixy="2e-05" iyz="0.214852" ixz="-1e-05"/>
  </inertial>
  <visual>
    <origin xyz="0.195 -0.554944 -0.454952" rpy="0 0 0"/>
    <geometry>
      <mesh filename="file://$(find Gwenbot_description)/meshes/leg_2_link_3_1.stl" scale="0.001 0.001 0.001"/>
    </geometry>
    <material name="silver"/>
  </visual>
  <collision>
    <origin xyz="0.195 -0.554944 -0.454952" rpy="0 0 0"/>
    <geometry>
      <mesh filename="file://$(find Gwenbot_description)/meshes/leg_2_link_3_1.stl" scale="0.001 0.001 0.001"/>
    </geometry>
  </collision>
</link>

<link name="leg_2_link_4_1">
  <inertial>
    <origin xyz="-0.03697762399539967 -0.01388151242503266 -0.1020564598305197" rpy="0 0 0"/>
    <mass value="19.12295749707096"/>
    <inertia ixx="0.184653" iyy="0.17484" izz="0.027319" ixy="-3e-06" iyz="-0.020683" ixz="-4.1e-05"/>
  </inertial>
  <visual>
    <origin xyz="0.195 -0.904944 -0.279952" rpy="0 0 0"/>
    <geometry>
      <mesh filename="file://$(find Gwenbot_description)/meshes/leg_2_link_4_1.stl" scale="0.001 0.001 0.001"/>
    </geometry>
    <material name="silver"/>
  </visual>
  <collision>
    <origin xyz="0.195 -0.904944 -0.279952" rpy="0 0 0"/>
    <geometry>
      <mesh filename="file://$(find Gwenbot_description)/meshes/leg_2_link_4_1.stl" scale="0.001 0.001 0.001"/>
    </geometry>
  </collision>
</link>

<link name="leg_3_link_2_1">
  <inertial>
    <origin xyz="0.0373717066639955 -0.0974379477549418 0.09744152705144904" rpy="0 0 0"/>
    <mass value="26.11095087959199"/>
    <inertia ixx="0.363269" iyy="0.193803" izz="0.193792" ixy="-1.1e-05" iyz="0.154975" ixz="1.1e-05"/>
  </inertial>
  <visual>
    <origin xyz="-0.195 0.34 -0.24" rpy="0 0 0"/>
    <geometry>
      <mesh filename="file://$(find Gwenbot_description)/meshes/leg_3_link_2_1.stl" scale="0.001 0.001 0.001"/>
    </geometry>
    <material name="silver"/>
  </visual>
  <collision>
    <origin xyz="-0.195 0.34 -0.24" rpy="0 0 0"/>
    <geometry>
      <mesh filename="file://$(find Gwenbot_description)/meshes/leg_3_link_2_1.stl" scale="0.001 0.001 0.001"/>
    </geometry>
  </collision>
</link>

<link name="leg_3_link_3_1">
  <inertial>
    <origin xyz="-0.03487554397484538 -0.16139040038524788 -0.08069565156547553" rpy="0 0 0"/>
    <mass value="29.576800336906427"/>
    <inertia ixx="0.597322" iyy="0.149521" izz="0.471799" ixy="2e-05" iyz="-0.214852" ixz="1e-05"/>
  </inertial>
  <visual>
    <origin xyz="-0.195 0.554944 -0.454952" rpy="0 0 0"/>
    <geometry>
      <mesh filename="file://$(find Gwenbot_description)/meshes/leg_3_link_3_1.stl" scale="0.001 0.001 0.001"/>
    </geometry>
    <material name="silver"/>
  </visual>
  <collision>
    <origin xyz="-0.195 0.554944 -0.454952" rpy="0 0 0"/>
    <geometry>
      <mesh filename="file://$(find Gwenbot_description)/meshes/leg_3_link_3_1.stl" scale="0.001 0.001 0.001"/>
    </geometry>
  </collision>
</link>

<link name="leg_3_link_4_1">
  <inertial>
    <origin xyz="0.03697762399539975 0.01388151242503255 -0.10205645983051956" rpy="0 0 0"/>
    <mass value="19.122957497070978"/>
    <inertia ixx="0.184653" iyy="0.17484" izz="0.027319" ixy="-3e-06" iyz="0.020683" ixz="4.1e-05"/>
  </inertial>
  <visual>
    <origin xyz="-0.195 0.904944 -0.279952" rpy="0 0 0"/>
    <geometry>
      <mesh filename="file://$(find Gwenbot_description)/meshes/leg_3_link_4_1.stl" scale="0.001 0.001 0.001"/>
    </geometry>
    <material name="silver"/>
  </visual>
  <collision>
    <origin xyz="-0.195 0.904944 -0.279952" rpy="0 0 0"/>
    <geometry>
      <mesh filename="file://$(find Gwenbot_description)/meshes/leg_3_link_4_1.stl" scale="0.001 0.001 0.001"/>
    </geometry>
  </collision>
</link>

<link name="leg_4_link_2_1">
  <inertial>
    <origin xyz="-0.03737170666399553 -0.09743794775494186 0.09744152705144915" rpy="0 0 0"/>
    <mass value="26.110950879591996"/>
    <inertia ixx="0.363269" iyy="0.193803" izz="0.193792" ixy="1.1e-05" iyz="0.154975" ixz="-1.1e-05"/>
  </inertial>
  <visual>
    <origin xyz="0.195 0.34 -0.24" rpy="0 0 0"/>
    <geometry>
      <mesh filename="file://$(find Gwenbot_description)/meshes/leg_4_link_2_1.stl" scale="0.001 0.001 0.001"/>
    </geometry>
    <material name="silver"/>
  </visual>
  <collision>
    <origin xyz="0.195 0.34 -0.24" rpy="0 0 0"/>
    <geometry>
      <mesh filename="file://$(find Gwenbot_description)/meshes/leg_4_link_2_1.stl" scale="0.001 0.001 0.001"/>
    </geometry>
  </collision>
</link>

<link name="leg_4_link_3_1">
  <inertial>
    <origin xyz="0.03487554397484535 -0.1613904003852481 -0.08069565156547548" rpy="0 0 0"/>
    <mass value="29.576800336906405"/>
    <inertia ixx="0.597322" iyy="0.149521" izz="0.471799" ixy="-2e-05" iyz="-0.214852" ixz="-1e-05"/>
  </inertial>
  <visual>
    <origin xyz="0.195 0.554944 -0.454952" rpy="0 0 0"/>
    <geometry>
      <mesh filename="file://$(find Gwenbot_description)/meshes/leg_4_link_3_1.stl" scale="0.001 0.001 0.001"/>
    </geometry>
    <material name="silver"/>
  </visual>
  <collision>
    <origin xyz="0.195 0.554944 -0.454952" rpy="0 0 0"/>
    <geometry>
      <mesh filename="file://$(find Gwenbot_description)/meshes/leg_4_link_3_1.stl" scale="0.001 0.001 0.001"/>
    </geometry>
  </collision>
</link>

<link name="leg_4_link_4_1">
  <inertial>
    <origin xyz="-0.03697762399539972 0.01388151242503266 -0.10205645983051972" rpy="0 0 0"/>
    <mass value="19.122957497070963"/>
    <inertia ixx="0.184653" iyy="0.17484" izz="0.027319" ixy="3e-06" iyz="0.020683" ixz="-4.1e-05"/>
  </inertial>
  <visual>
    <origin xyz="0.195 0.904944 -0.279952" rpy="0 0 0"/>
    <geometry>
      <mesh filename="file://$(find Gwenbot_description)/meshes/leg_4_link_4_1.stl" scale="0.001 0.001 0.001"/>
    </geometry>
    <material name="silver"/>
  </visual>
  <collision>
    <origin xyz="0.195 0.904944 -0.279952" rpy="0 0 0"/>
    <geometry>
      <mesh filename="file://$(find Gwenbot_description)/meshes/leg_4_link_4_1.stl" scale="0.001 0.001 0.001"/>
    </geometry>
  </collision>
</link>

<link name="leg_1_link_1_1">
  <inertial>
    <origin xyz="2.7755575615628914e-17 0.16061611503732448 0.00393919575366905" rpy="0 0 0"/>
    <mass value="66.2235956819387"/>
    <inertia ixx="1.043665" iyy="0.491909" izz="0.765529" ixy="0.0" iyz="-0.215809" ixz="0.0"/>
  </inertial>
  <visual>
    <origin xyz="-0.125 -0.125 -0.15" rpy="0 0 0"/>
    <geometry>
      <mesh filename="file://$(find Gwenbot_description)/meshes/leg_1_link_1_1.stl" scale="0.001 0.001 0.001"/>
    </geometry>
    <material name="silver"/>
  </visual>
  <collision>
    <origin xyz="-0.125 -0.125 -0.15" rpy="0 0 0"/>
    <geometry>
      <mesh filename="file://$(find Gwenbot_description)/meshes/leg_1_link_1_1.stl" scale="0.001 0.001 0.001"/>
    </geometry>
  </collision>
</link>

<link name="leg_2_link_1_1">
  <inertial>
    <origin xyz="-2.7755575615628914e-17 0.16061611503732443 0.00393919575366905" rpy="0 0 0"/>
    <mass value="66.22359568193872"/>
    <inertia ixx="1.043665" iyy="0.491909" izz="0.765529" ixy="-0.0" iyz="-0.215809" ixz="-0.0"/>
  </inertial>
  <visual>
    <origin xyz="0.125 -0.125 -0.15" rpy="0 0 0"/>
    <geometry>
      <mesh filename="file://$(find Gwenbot_description)/meshes/leg_2_link_1_1.stl" scale="0.001 0.001 0.001"/>
    </geometry>
    <material name="silver"/>
  </visual>
  <collision>
    <origin xyz="0.125 -0.125 -0.15" rpy="0 0 0"/>
    <geometry>
      <mesh filename="file://$(find Gwenbot_description)/meshes/leg_2_link_1_1.stl" scale="0.001 0.001 0.001"/>
    </geometry>
  </collision>
</link>

<link name="leg_3_link_1_1">
  <inertial>
    <origin xyz="0.0 -0.16061611503732443 0.00393919575366905" rpy="0 0 0"/>
    <mass value="66.2235956819387"/>
    <inertia ixx="1.043665" iyy="0.491909" izz="0.765529" ixy="-0.0" iyz="0.215809" ixz="0.0"/>
  </inertial>
  <visual>
    <origin xyz="-0.125 0.125 -0.15" rpy="0 0 0"/>
    <geometry>
      <mesh filename="file://$(find Gwenbot_description)/meshes/leg_3_link_1_1.stl" scale="0.001 0.001 0.001"/>
    </geometry>
    <material name="silver"/>
  </visual>
  <collision>
    <origin xyz="-0.125 0.125 -0.15" rpy="0 0 0"/>
    <geometry>
      <mesh filename="file://$(find Gwenbot_description)/meshes/leg_3_link_1_1.stl" scale="0.001 0.001 0.001"/>
    </geometry>
  </collision>
</link>

<link name="leg_4_link_1_1">
  <inertial>
    <origin xyz="-2.7755575615628914e-17 -0.16061611503732448 0.003939195753669078" rpy="0 0 0"/>
    <mass value="66.2235956819387"/>
    <inertia ixx="1.043665" iyy="0.491909" izz="0.765529" ixy="0.0" iyz="0.215809" ixz="-0.0"/>
  </inertial>
  <visual>
    <origin xyz="0.125 0.125 -0.15" rpy="0 0 0"/>
    <geometry>
      <mesh filename="file://$(find Gwenbot_description)/meshes/leg_4_link_1_1.stl" scale="0.001 0.001 0.001"/>
    </geometry>
    <material name="silver"/>
  </visual>
  <collision>
    <origin xyz="0.125 0.125 -0.15" rpy="0 0 0"/>
    <geometry>
      <mesh filename="file://$(find Gwenbot_description)/meshes/leg_4_link_1_1.stl" scale="0.001 0.001 0.001"/>
    </geometry>
  </collision>
</link>

<link name="camera_joint_1">
  <inertial>
    <origin xyz="0.016260409832481927 -3.495815603183003e-17 0.0760138865857079" rpy="0 0 0"/>
    <mass value="130.70773462841575"/>
    <inertia ixx="1.275998" iyy="1.586045" izz="2.399393" ixy="-0.0" iyz="-0.0" ixz="-0.029726"/>
  </inertial>
  <visual>
    <origin xyz="-0.0 -0.0 -0.425" rpy="0 0 0"/>
    <geometry>
      <mesh filename="file://$(find Gwenbot_description)/meshes/camera_joint_1.stl" scale="0.001 0.001 0.001"/>
    </geometry>
    <material name="silver"/>
  </visual>
  <collision>
    <origin xyz="-0.0 -0.0 -0.425" rpy="0 0 0"/>
    <geometry>
      <mesh filename="file://$(find Gwenbot_description)/meshes/camera_joint_1.stl" scale="0.001 0.001 0.001"/>
    </geometry>
  </collision>
</link>

<joint name="leg_1_joint_1" type="revolute">
  <origin xyz="0.125 0.125 0.15" rpy="0 0 0"/>
  <parent link="base_link"/>
  <child link="leg_1_link_1_1"/>
  <axis xyz="0.0 0.0 -1.0"/>
  <limit upper="0.174533" lower="-0.174533" effort="100" velocity="100"/>
</joint>

<joint name="leg_1_joint_2" type="revolute">
  <origin xyz="0.07 0.215 0.09" rpy="0 0 0"/>
  <parent link="leg_1_link_1_1"/>
  <child link="leg_1_link_2_1"/>
  <axis xyz="-1.0 0.0 0.0"/>
  <limit upper="0.872665" lower="-0.872665" effort="100" velocity="100"/>
</joint>

<joint name="leg_1_joint_3" type="revolute">
  <origin xyz="0.0 0.214944 0.214952" rpy="0 0 0"/>
  <parent link="leg_1_link_2_1"/>
  <child link="leg_1_link_3_1"/>
  <axis xyz="1.0 0.0 0.0"/>
  <limit upper="3.577925" lower="-1.134464" effort="100" velocity="100"/>
</joint>

<joint name="leg_1_joint_4" type="continuous">
  <origin xyz="0.0 0.35 -0.175" rpy="0 0 0"/>
  <parent link="leg_1_link_3_1"/>
  <child link="leg_1_link_4_1"/>
  <axis xyz="-1.0 0.0 0.0"/>
</joint>


<joint name="leg_2_joint_1" type="revolute">
  <origin xyz="-0.125 0.125 0.15" rpy="0 0 0"/>
  <parent link="base_link"/>
  <child link="leg_2_link_1_1"/>
  <axis xyz="0.0 0.0 -1.0"/>
  <limit upper="0.174533" lower="-0.174533" effort="100" velocity="100"/>
</joint>

<joint name="leg_2_joint_2" type="revolute">
  <origin xyz="-0.07 0.215 0.09" rpy="0 0 0"/>
  <parent link="leg_2_link_1_1"/>
  <child link="leg_2_link_2_1"/>
  <axis xyz="-1.0 0.0 0.0"/>
  <limit upper="0.872665" lower="-0.872665" effort="100" velocity="100"/>
</joint>

<joint name="leg_2_joint_3" type="revolute">
  <origin xyz="0.0 0.214944 0.214952" rpy="0 0 0"/>
  <parent link="leg_2_link_2_1"/>
  <child link="leg_2_link_3_1"/>
  <axis xyz="1.0 0.0 0.0"/>
  <limit upper="3.577925" lower="-1.134464" effort="100" velocity="100"/>
</joint>

<joint name="leg_2_joint_4" type="continuous">
  <origin xyz="0.0 0.35 -0.175" rpy="0 0 0"/>
  <parent link="leg_2_link_3_1"/>
  <child link="leg_2_link_4_1"/>
  <axis xyz="-1.0 0.0 0.0"/>
</joint>


<joint name="leg_3_joint_1" type="revolute">
  <origin xyz="0.125 -0.125 0.15" rpy="0 0 0"/>
  <parent link="base_link"/>
  <child link="leg_3_link_1_1"/>
  <axis xyz="0.0 0.0 1.0"/>
  <limit upper="0.174533" lower="-0.174533" effort="100" velocity="100"/>
</joint>


<joint name="leg_3_joint_2" type="revolute">
  <origin xyz="0.07 -0.215 0.09" rpy="0 0 0"/>
  <parent link="leg_3_link_1_1"/>
  <child link="leg_3_link_2_1"/>
  <axis xyz="1.0 0.0 0.0"/>
  <limit upper="0.872665" lower="-0.872665" effort="100" velocity="100"/>
</joint>

<joint name="leg_3_joint_3" type="revolute">
  <origin xyz="0.0 -0.214944 0.214952" rpy="0 0 0"/>
  <parent link="leg_3_link_2_1"/>
  <child link="leg_3_link_3_1"/>
  <axis xyz="-1.0 0.0 0.0"/>
  <limit upper="3.577925" lower="-1.134464" effort="100" velocity="100"/>
</joint>

<joint name="leg_3_joint_4" type="continuous">
  <origin xyz="0.0 -0.35 -0.175" rpy="0 0 0"/>
  <parent link="leg_3_link_3_1"/>
  <child link="leg_3_link_4_1"/>
  <axis xyz="1.0 0.0 0.0"/>
</joint>



<joint name="leg_4_joint_1" type="revolute">
  <origin xyz="-0.125 -0.125 0.15" rpy="0 0 0"/>
  <parent link="base_link"/>
  <child link="leg_4_link_1_1"/>
  <axis xyz="0.0 0.0 1.0"/>
  <limit upper="0.174533" lower="-0.174533" effort="100" velocity="100"/>
</joint>


<joint name="leg_4_joint_2" type="revolute">
  <origin xyz="-0.07 -0.215 0.09" rpy="0 0 0"/>
  <parent link="leg_4_link_1_1"/>
  <child link="leg_4_link_2_1"/>
  <axis xyz="1.0 0.0 0.0"/>
  <limit upper="0.872665" lower="-0.872665" effort="100" velocity="100"/>
</joint>

<joint name="leg_4_joint_3" type="revolute">
  <origin xyz="0.0 -0.214944 0.214952" rpy="0 0 0"/>
  <parent link="leg_4_link_2_1"/>
  <child link="leg_4_link_3_1"/>
  <axis xyz="-1.0 0.0 0.0"/>
  <limit upper="3.577925" lower="-1.134464" effort="100" velocity="100"/>
</joint>

<joint name="leg_4_joint_4" type="continuous">
  <origin xyz="0.0 -0.35 -0.175" rpy="0 0 0"/>
  <parent link="leg_4_link_3_1"/>
  <child link="leg_4_link_4_1"/>
  <axis xyz="1.0 0.0 0.0"/>
</joint>



<joint name="camera_joint" type="fixed">
  <origin xyz="0.0 0.0 0.425" rpy="0 0 0"/>
  <parent link="base_link"/>
  <child link="camera_joint_1"/>
</joint>

</robot>
