<?xml version="1.0" ?>
<robot name="Gripper" xmlns:xacro="http://www.ros.org/wiki/xacro">

<xacro:include filename="$(find Gripper_description)/urdf/materials.xacro" />
<xacro:include filename="$(find Gripper_description)/urdf/Gripper.trans" />
<xacro:include filename="$(find Gripper_description)/urdf/Gripper.gazebo" />
<link name="base_link">
  <inertial>
    <origin xyz="0.0 -3.2606564537310286e-17 0.11289552544712034" rpy="0 0 0"/>
    <mass value="70.06720037124329"/>
    <inertia ixx="0.63631" iyy="0.698888" izz="0.452049" ixy="0.0" iyz="-0.0" ixz="-0.0"/>
  </inertial>
  <visual>
    <origin xyz="0 0 0" rpy="0 0 0"/>
    <geometry>
      <mesh filename="file://$(find Gripper_description)/meshes/base_link.stl" scale="0.001 0.001 0.001"/>
    </geometry>
    <material name="silver"/>
  </visual>
  <collision>
    <origin xyz="0 0 0" rpy="0 0 0"/>
    <geometry>
      <mesh filename="file://$(find Gripper_description)/meshes/base_link.stl" scale="0.001 0.001 0.001"/>
    </geometry>
  </collision>
</link>

<link name="gripper_1_1">
  <inertial>
    <origin xyz="-0.09946048127226001 -0.028182181818181825 0.14649874253143086" rpy="0 0 0"/>
    <mass value="8.96261797713013"/>
    <inertia ixx="0.085405" iyy="0.10949" izz="0.027819" ixy="0.0" iyz="-0.0" ixz="0.024967"/>
  </inertial>
  <visual>
    <origin xyz="0.12 -0.028182 -0.3" rpy="0 0 0"/>
    <geometry>
      <mesh filename="file://$(find Gripper_description)/meshes/gripper_1_1.stl" scale="0.001 0.001 0.001"/>
    </geometry>
    <material name="silver"/>
  </visual>
  <collision>
    <origin xyz="0.12 -0.028182 -0.3" rpy="0 0 0"/>
    <geometry>
      <mesh filename="file://$(find Gripper_description)/meshes/gripper_1_1.stl" scale="0.001 0.001 0.001"/>
    </geometry>
  </collision>
</link>

<link name="gripper_2_1">
  <inertial>
    <origin xyz="0.09946048127225995 -0.028182181818181818 0.14649874253143097" rpy="0 0 0"/>
    <mass value="8.96261797713013"/>
    <inertia ixx="0.085405" iyy="0.10949" izz="0.027819" ixy="-0.0" iyz="0.0" ixz="-0.024967"/>
  </inertial>
  <visual>
    <origin xyz="-0.12 -0.028182 -0.3" rpy="0 0 0"/>
    <geometry>
      <mesh filename="file://$(find Gripper_description)/meshes/gripper_2_1.stl" scale="0.001 0.001 0.001"/>
    </geometry>
    <material name="silver"/>
  </visual>
  <collision>
    <origin xyz="-0.12 -0.028182 -0.3" rpy="0 0 0"/>
    <geometry>
      <mesh filename="file://$(find Gripper_description)/meshes/gripper_2_1.stl" scale="0.001 0.001 0.001"/>
    </geometry>
  </collision>
</link>

<joint name="Revolute 1" type="revolute">
  <origin xyz="-0.12 0.028182 0.3" rpy="0 0 0"/>
  <parent link="base_link"/>
  <child link="gripper_1_1"/>
  <axis xyz="0.0 -1.0 0.0"/>
  <limit upper="1.658063" lower="-0.610865" effort="100" velocity="100"/>
</joint>

<joint name="Revolute 2" type="revolute">
  <origin xyz="0.12 0.028182 0.3" rpy="0 0 0"/>
  <parent link="base_link"/>
  <child link="gripper_2_1"/>
  <axis xyz="0.0 1.0 0.0"/>
  <limit upper="1.658063" lower="-0.610865" effort="100" velocity="100"/>
</joint>

</robot>
